Workbook
Name cop: #REF!
Name NativeTimeline_Order_Date: #N/A
Name Slicer_City: #N/A
Name Slicer_Gender: #N/A

Sheet data
A1: Customer_ID | B1: First_Name | C1: Last_Name | D1: Full_Name | E1: Age | F1: Gender | G1: City | H1: Email | I1: Domain | J1: Address | K1: Order_ID | L1: Order_Date | M1: Order_Time | N1: Product_ID | O1: Price | P1: Quantity | Q1: Amount | R1: Coupon_Code | S1: Discount_Percent | T1: Estimated_Days_to_Deliver | U1: Delivery_Charge | V1: Amount_with_Del_chrg | W1: Discount_Amount | X1: Final_Amount | Y1: Delivery_Date | Z1: Delivery_Time | AA1: Days_To_Deliver | AB1: IsLateDelivery
A2: CID186 | B2: Anne | C2: Oconnell | D2: =CONCATENATE(B2," ",C2) -> Anne Oconnell | E2: 37 | F2: Male | G2: Phoenix | H2: anne.oconnell@outlook.com | I2: =RIGHT(H2,LEN(H2)-SEARCH("@",H2,1)) -> outlook.com | J2: 2850 Matthew Ford, North Yolandachester, FL 67488 | K2: OID2497 | L2: 45358 | M2: 18:16:33 | N2: PID022 | O2: 308.88 | P2: 5 | Q2: =O2*P2 -> 1544.4 | R2: FLAT8 | S2: =IF(R2="FLAT8",8%,IF(R2="FLAT10",10%,IF(R2="FLAT15",15%,IF(R2="FLAT20",20%,0)))) -> 0.08 | T2: 4 | U2: 60 | V2: =IF(R2="DEL0",Q2,Q2+U2) -> 1604.4 | W2: =V2*S2 -> 128.352 | X2: =V2-V2*S2 -> 1476.048 | Y2: 45361 | Z2: 08:51:31 | AA2: =_xlfn.DAYS(Y2,L2) -> 3 | AB2: =IF(T2=AA2,"InTime",IF(T2>AA2,"BeforeTime","Late")) -> BeforeTime
A3: CID150 | B3: Anthony | C3: Thomas | D3: =CONCATENATE(B3," ",C3) -> Anthony Thomas | E3: 53 | F3: Female | G3: Houston | H3: anthony.thomas@rediffmail.com | I3: =RIGHT(H3,LEN(H3)-SEARCH("@",H3,1)) -> rediffmail.com | J3: 931 Christopher Ways Suite 833, North Michelle, IN 53484 | K3: OID7056 | L3: 45378 | M3: 01:46:33 | N3: PID015 | O3: 166.28 | P3: 4 | Q3: =O3*P3 -> 665.12 | R3: FLAT8 | S3: =IF(R3="FLAT8",8%,IF(R3="FLAT10",10%,IF(R3="FLAT15",15%,IF(R3="FLAT20",20%,0)))) -> 0.08 | T3: 7 | U3: 66 | V3: =IF(R3="DEL0",Q3,Q3+U3) -> 731.12 | W3: =V3*S3 -> 58.4896 | X3: =V3-V3*S3 -> 672.6304 | Y3: 45381 | Z3: 18:46:26 | AA3: =_xlfn.DAYS(Y3,L3) -> 3 | AB3: =IF(T3=AA3,"InTime",IF(T3>AA3,"BeforeTime","Late")) -> BeforeTime
A4: CID115 | B4: Karl | C4: Gallagher | D4: =CONCATENATE(B4," ",C4) -> Karl Gallagher | E4: 60 | F4: Other | G4: Phoenix | H4: karl.gallagher@rediffmail.com | I4: =RIGHT(H4,LEN(H4)-SEARCH("@",H4,1)) -> rediffmail.com | J4: 5016 Snow Mountains Apt. 063, New Seanport, WY 41492 | K4: OID7502 | L4: 45342 | M4: 07:31:36 | N4: PID023 | O4: 202.54 | P4: 1 | Q4: =O4*P4 -> 202.54 | R4: FLAT15 | S4: =IF(R4="FLAT8",8%,IF(R4="FLAT10",10%,IF(R4="FLAT15",15%,IF(R4="FLAT20",20%,0)))) -> 0.15 | T4: 3 | U4: 47 | V4: =IF(R4="DEL0",Q4,Q4+U4) -> 249.54 | W4: =V4*S4 -> 37.431 | X4: =V4-V4*S4 -> 212.109 | Y4: 45344 | Z4: 14:29:50 | AA4: =_xlfn.DAYS(Y4,L4) -> 2 | AB4: =IF(T4=AA4,"InTime",IF(T4>AA4,"BeforeTime","Late")) -> BeforeTime
A5: CID115 | B5: Karl | C5: Gallagher | D5: =CONCATENATE(B5," ",C5) -> Karl Gallagher | E5: 60 | F5: Other | G5: Phoenix | H5: karl.gallagher@rediffmail.com | I5: =RIGHT(H5,LEN(H5)-SEARCH("@",H5,1)) -> rediffmail.com | J5: 5016 Snow Mountains Apt. 063, New Seanport, WY 41492 | K5: OID7077 | L5: 45426 | M5: 18:29:21 | N5: PID031 | O5: 405 | P5: 5 | Q5: =O5*P5 -> 2025 | R5: DEL0 | S5: =IF(R5="FLAT8",8%,IF(R5="FLAT10",10%,IF(R5="FLAT15",15%,IF(R5="FLAT20",20%,0)))) -> 0 | T5: 6 | U5: 47 | V5: =IF(R5="DEL0",Q5,Q5+U5) -> 2025 | W5: =V5*S5 -> 0 | X5: =V5-V5*S5 -> 2025 | Y5: 45430 | Z5: 07:00:32 | AA5: =_xlfn.DAYS(Y5,L5) -> 4 | AB5: =IF(T5=AA5,"InTime",IF(T5>AA5,"BeforeTime","Late")) -> BeforeTime
A6: CID149 | B6: Angela | C6: Horne | D6: =CONCATENATE(B6," ",C6) -> Angela Horne | E6: 49 | F6: Other | G6: Phoenix | H6: angela.horne@outlook.com | I6: =RIGHT(H6,LEN(H6)-SEARCH("@",H6,1)) -> outlook.com | J6: USNV Mueller, FPO AP 54648 | K6: OID2793 | L6: 45391 | M6: 03:23:21 | N6: PID015 | O6: 166.28 | P6: 1 | Q6: =O6*P6 -> 166.28 | R6: FLAT8 | S6: =IF(R6="FLAT8",8%,IF(R6="FLAT10",10%,IF(R6="FLAT15",15%,IF(R6="FLAT20",20%,0)))) -> 0.08 | T6: 2 | U6: 54 | V6: =IF(R6="DEL0",Q6,Q6+U6) -> 220.28 | W6: =V6*S6 -> 17.6224 | X6: =V6-V6*S6 -> 202.6576 | Y6: 45395 | Z6: 22:10:58 | AA6: =_xlfn.DAYS(Y6,L6) -> 4 | AB6: =IF(T6=AA6,"InTime",IF(T6>AA6,"BeforeTime","Late")) -> Late
A7: CID159 | B7: Christine | C7: West | D7: =CONCATENATE(B7," ",C7) -> Christine West | E7: 53 | F7: Other | G7: New York | H7: christine.west@gmail.com | I7: =RIGHT(H7,LEN(H7)-SEARCH("@",H7,1)) -> gmail.com | J7: Unit 1433 Box 0246, DPO AP 94952 | K7: OID1483 | L7: 45543 | M7: 16:55:06 | N7: PID043 | O7: 330.11 | P7: 4 | Q7: =O7*P7 -> 1320.44 | R7: FLAT15 | S7: =IF(R7="FLAT8",8%,IF(R7="FLAT10",10%,IF(R7="FLAT15",15%,IF(R7="FLAT20",20%,0)))) -> 0.15 | T7: 6 | U7: 39 | V7: =IF(R7="DEL0",Q7,Q7+U7) -> 1359.44 | W7: =V7*S7 -> 203.916 | X7: =V7-V7*S7 -> 1155.524 | Y7: 45547 | Z7: 11:25:50 | AA7: =_xlfn.DAYS(Y7,L7) -> 4 | AB7: =IF(T7=AA7,"InTime",IF(T7>AA7,"BeforeTime","Late")) -> BeforeTime
A8: CID115 | B8: Karl | C8: Gallagher | D8: =CONCATENATE(B8," ",C8) -> Karl Gallagher | E8: 60 | F8: Other | G8: Phoenix | H8: karl.gallagher@rediffmail.com | I8: =RIGHT(H8,LEN(H8)-SEARCH("@",H8,1)) -> rediffmail.com | J8: 5016 Snow Mountains Apt. 063, New Seanport, WY 41492 | K8: OID4105 | L8: 45662 | M8: 09:47:21 | N8: PID022 | O8: 308.88 | P8: 5 | Q8: =O8*P8 -> 1544.4 | R8: FLAT20 | S8: =IF(R8="FLAT8",8%,IF(R8="FLAT10",10%,IF(R8="FLAT15",15%,IF(R8="FLAT20",20%,0)))) -> 0.2 | T8: 5 | U8: 47 | V8: =IF(R8="DEL0",Q8,Q8+U8) -> 1591.4 | W8: =V8*S8 -> 318.28 | X8: =V8-V8*S8 -> 1273.12 | Y8: 45665 | Z8: 20:10:50 | AA8: =_xlfn.DAYS(Y8,L8) -> 3 | AB8: =IF(T8=AA8,"InTime",IF(T8>AA8,"BeforeTime","Late")) -> BeforeTime
A9: CID198 | B9: David | C9: Delacruz | D9: =CONCATENATE(B9," ",C9) -> David Delacruz | E9: 26 | F9: Female | G9: Los Angeles | H9: david.delacruz@rediffmail.com | I9: =RIGHT(H9,LEN(H9)-SEARCH("@",H9,1)) -> rediffmail.com | J9: USNS Ray, FPO AE 20238 | K9: OID4372 | L9: 45459 | M9: 19:27:45 | N9: PID046 | O9: 363.64 | P9: 3 | Q9: =O9*P9 -> 1090.92 | R9: FLAT10 | S9: =IF(R9="FLAT8",8%,IF(R9="FLAT10",10%,IF(R9="FLAT15",15%,IF(R9="FLAT20",20%,0)))) -> 0.1 | T9: 2 | U9: 70 | V9: =IF(R9="DEL0",Q9,Q9+U9) -> 1160.92 | W9: =V9*S9 -> 116.092 | X9: =V9-V9*S9 -> 1044.828 | Y9: 45464 | Z9: 12:36:32 | AA9: =_xlfn.DAYS(Y9,L9) -> 5 | AB9: =IF(T9=AA9,"InTime",IF(T9>AA9,"BeforeTime","Late")) -> Late
A10: CID152 | B10: Marcus | C10: Valenzuela | D10: =CONCATENATE(B10," ",C10) -> Marcus Valenzuela | E10: 39 | F10: Male | G10: Phoenix | H10: marcus.valenzuela@yahoo.com | I10: =RIGHT(H10,LEN(H10)-SEARCH("@",H10,1)) -> yahoo.com | J10: 694 Graham Prairie Apt. 887, Jimenezfurt, MI 33044 | K10: OID3528 | L10: 45040 | M10: 12:07:00 | N10: PID034 | O10: 275.44 | P10: 1 | Q10: =O10*P10 -> 275.44 | R10: FLAT8 | S10: =IF(R10="FLAT8",8%,IF(R10="FLAT10",10%,IF(R10="FLAT15",15%,IF(R10="FLAT20",20%,0)))) -> 0.08 | T10: 7 | U10: 63 | V10: =IF(R10="DEL0",Q10,Q10+U10) -> 338.44 | W10: =V10*S10 -> 27.0752 | X10: =V10-V10*S10 -> 311.3648 | Y10: 45042 | Z10: 23:05:41 | AA10: =_xlfn.DAYS(Y10,L10) -> 2 | AB10: =IF(T10=AA10,"InTime",IF(T10>AA10,"BeforeTime","Late")) -> BeforeTime
A11: CID130 | B11: Debra | C11: Rodriguez | D11: =CONCATENATE(B11," ",C11) -> Debra Rodriguez | E11: 48 | F11: Other | G11: Houston | H11: debra.rodriguez@rediffmail.com | I11: =RIGHT(H11,LEN(H11)-SEARCH("@",H11,1)) -> rediffmail.com | J11: Unit 5964 Box 0721, DPO AP 01840 | K11: OID9634 | L11: 45282 | M11: 13:46:47 | N11: PID033 | O11: 48.45 | P11: 1 | Q11: =O11*P11 -> 48.45 | R11: FLAT15 | S11: =IF(R11="FLAT8",8%,IF(R11="FLAT10",10%,IF(R11="FLAT15",15%,IF(R11="FLAT20",20%,0)))) -> 0.15 | T11: 7 | U11: 59 | V11: =IF(R11="DEL0",Q11,Q11+U11) -> 107.45 | W11: =V11*S11 -> 16.1175 | X11: =V11-V11*S11 -> 91.3325 | Y11: 45287 | Z11: 19:57:06 | AA11: =_xlfn.DAYS(Y11,L11) -> 5 | AB11: =IF(T11=AA11,"InTime",IF(T11>AA11,"BeforeTime","Late")) -> BeforeTime
A12: CID115 | B12: Karl | C12: Gallagher | D12: =CONCATENATE(B12," ",C12) -> Karl Gallagher | E12: 60 | F12: Other | G12: Phoenix | H12: karl.gallagher@rediffmail.com | I12: =RIGHT(H12,LEN(H12)-SEARCH("@",H12,1)) -> rediffmail.com | J12: 5016 Snow Mountains Apt. 063, New Seanport, WY 41492 | K12: OID1905 | L12: 45588 | M12: 17:21:43 | N12: PID046 | O12: 363.64 | P12: 4 | Q12: =O12*P12 -> 1454.56 | R12: DEL0 | S12: =IF(R12="FLAT8",8%,IF(R12="FLAT10",10%,IF(R12="FLAT15",15%,IF(R12="FLAT20",20%,0)))) -> 0 | T12: 2 | U12: 35 | V12: =IF(R12="DEL0",Q12,Q12+U12) -> 1454.56 | W12: =V12*S12 -> 0 | X12: =V12-V12*S12 -> 1454.56 | Y12: 45590 | Z12: 08:00:35 | AA12: =_xlfn.DAYS(Y12,L12) -> 2 | AB12: =IF(T12=AA12,"InTime",IF(T12>AA12,"BeforeTime","Late")) -> InTime
A13: CID101 | B13: Bobby | C13: Forbes | D13: =CONCATENATE(B13," ",C13) -> Bobby Forbes | E13: 20 | F13: Male | G13: Los Angeles | H13: bobby.forbes@gmail.com | I13: =RIGHT(H13,LEN(H13)-SEARCH("@",H13,1)) -> gmail.com | J13: 3079 John Parkway Suite 961, Port Kristaview, MT 91019 | K13: OID3136 | L13: 45498 | M13: 15:09:49 | N13: PID007 | O13: 257.06 | P13: 3 | Q13: =O13*P13 -> 771.18 | R13: DEL0 | S13: =IF(R13="FLAT8",8%,IF(R13="FLAT10",10%,IF(R13="FLAT15",15%,IF(R13="FLAT20",20%,0)))) -> 0 | T13: 7 | U13: 62 | V13: =IF(R13="DEL0",Q13,Q13+U13) -> 771.18 | W13: =V13*S13 -> 0 | X13: =V13-V13*S13 -> 771.18 | Y13: 45499 | Z13: 22:54:40 | AA13: =_xlfn.DAYS(Y13,L13) -> 1 | AB13: =IF(T13=AA13,"InTime",IF(T13>AA13,"BeforeTime","Late")) -> BeforeTime
... A501: CID158 | B501: Angela | C501: Evans | D501: =CONCATENATE(B501," ",C501) -> Angela Evans | E501: 52 | F501: Other | G501: Houston | H501: angela.evans@outlook.com | I501: =RIGHT(H501,LEN(H501)-SEARCH("@",H501,1)) -> outlook.com | J501: 16031 David Mountain Suite 431, Susanborough, PA 01910 | K501: OID6847 | L501: 45501 | M501: 17:02:09 | N501: PID010 | O501: 44.5 | P501: 4 | Q501: =O501*P501 -> 178 | R501: DEL0 | S501: =IF(R501="FLAT8",8%,IF(R501="FLAT10",10%,IF(R501="FLAT15",15%,IF(R501="FLAT20",20%,0)))) -> 0 | T501: 3 | U501: 45 | V501: =IF(R501="DEL0",Q501,Q501+U501) -> 178 | W501: =V501*S501 -> 0 | X501: =V501-V501*S501 -> 178 | Y501: 45504 | Z501: 05:55:32 | AA501: =_xlfn.DAYS(Y501,L501) -> 3 | AB501: =IF(T501=AA501,"InTime",IF(T501>AA501,"BeforeTime","Late")) -> InTime

Sheet Dashboard

Sheet KPIs
A1: Customer KPIs | B1: a) Find total Unique Customers | C1: =COUNTA(_xlfn.UNIQUE(data!A2:A501)) -> 100 | D1: =_xlfn.FORMULATEXT(C1) -> =COUNTA(UNIQUE(data!A2:A501))
B3: b) Customers with most orders | C3: Row Labels | D3: Count of Order_ID
C4: CID174 | D4: 11
C5: CID162 | D5: 11
C6: Grand Total | D6: 22
B8: c) Customers with highest total order amount | C8: Row Labels | D8: Sum of Amount
C9: CID174 | D9: 14040.5
C10: Grand Total | D10: 14040.5
B12: d)Average Customer Age | C12: =AVERAGE(data!E2:E501) -> 42.124 | D12: =_xlfn.FORMULATEXT(C12) -> =AVERAGE(data!E2:E501)
A15: Order and Delivery KPIs | B15: a)Total Orders placed | C15: =COUNTA(data!A2:A501) -> 500 | D15: =_xlfn.FORMULATEXT(C15) -> =COUNTA(data!A2:A501)
B17: b) Average Days to Deliver | C17: =AVERAGE(data!AA2:AA501) -> 4.002 | D17: =_xlfn.FORMULATEXT(C17) -> =AVERAGE(data!AA2:AA501)
B19: c) Total orders with 0 Delivery charge | C19: =COUNTIF(data!R2:R501,"Del0") -> 102 | D19: =_xlfn.FORMULATEXT(C19) -> =COUNTIF(data!R2:R501,"Del0")
A22: Product KPIs | B22: a)Find total Unique product | C22: =COUNTA(_xlfn.UNIQUE(data!N2:N501)) -> 50 | D22: =_xlfn.FORMULATEXT(C22) -> =COUNTA(UNIQUE(data!N2:N501))
B24: b) Most ordered product | C24: Row Labels | D24: Count of Order_ID
C25: PID036 | D25: 17
C26: Grand Total | D26: 17
B28: c) Product with generated highest revenue | C28: Row Labels | D28: Sum of Final_Amount
C29: PID027 | D29: 18815.537
C30: Grand Total | D30: 18815.537
A33: Sales KPIs | B33: a)Total Sales generated | C33: =SUM(data!Q2:Q501) -> 364289.49 | D33: =_xlfn.FORMULATEXT(C33) -> =SUM(data!Q2:Q501)
B35: b)Sum total discount Offered | C35: =SUM(data!W2:W501) -> 40687.91 | D35: =_xlfn.FORMULATEXT(C35) -> =SUM(data!W2:W501)
B37: c)Total Sales after discount | C37: =SUM(data!X2:X501) -> 344465.58 | D37: =_xlfn.FORMULATEXT(C37) -> =SUM(data!X2:X501)
B39: d)Average Sales(excl. Discount) | C39: =AVERAGE(data!Q2:Q501) -> 728.57898 | D39: =_xlfn.FORMULATEXT(C39) -> =AVERAGE(data!Q2:Q501)

Sheet Visual Analysis
A2: Visual Analysis
A3: 1) Represent top 10 customers with highest Total Sales after Discount on a bar chart
A5: Customer_ID | B5: Sum of Final_Amount
A6: CID174 | B6: 13002.119
A7: CID114 | B7: 8172.0983
A8: CID162 | B8: 7832.8487
A9: CID165 | B9: 7398.2038
A10: CID102 | B10: 6827.9278
A11: Grand Total | B11: 43233.197
A14: 2) Represent the count of different products ordered and its percentage on a donut chart
A16: Product_ID | B16: Sum of Quantity
A17: PID002 | B17: 51
A18: PID018 | B18: 44
A19: PID027 | B19: 42
A20: PID036 | B20: 48
A21: PID046 | B21: 48
A22: Grand Total | B22: 233
A25: 3) Represent city wise total orders on a Funnel Chart
A27: Row Labels | B27: Count of Order_ID
A28: Houston | B28: 80
A29: San Francisco | B29: 72
A30: Los Angeles | B30: 72
A31: Phoenix | B31: 66
A32: Dallas | B32: 64
A33: Chicago | B33: 51
A34: New York | B34: 51
A35: Miami | B35: 44
A36: Grand Total | B36: 500
A39: 4) Represent city wise total sales amount after discount
A41: Cities | B41: Sum of Sales
A42: Chicago | B42: 32981.927
A43: Dallas | B43: 45720.287
A44: Houston | B44: 59687.07
A45: Los Angeles | B45: 47151.856
A46: Miami | B46: 24522.095
A47: New York | B47: 39521.267
A48: Phoenix | B48: 45248.246
A49: San Francisco | B49: 49632.831
A50: Grand Total | B50: 344465.58
A53: 5) Represent top 5 and bottom 5 products with highest and lowest sales respectively
...
